Workbook

Sheet README
A1: Performance (DV) data for Step 6, round 2
A2: What this is | B2: Outcome data for the 52 acts, following the measures Harrison et al. (2023) collected: each studio album's Billboard 200 peak and RIAA certification, the act's later Grammy nominations, its years active and its album counts. Best Ever Albums rankings and SecondHandSongs cover counts are left for Step 11.
A3: Sheets | B3: Acts: one row per act, every figure a formula over the other sheets. Albums: one row per original studio album, from the final events file. Grammy nominations: one row per nomination at the Best New Artist ceremony (other categories) or later. Breaks: each breakup and the reunion that ended it, used for years active.
A4: Reference point | B4: 'After the ceremony' means after the act's Best New Artist ceremony. Albums dated only to a month are placed on the 15th, and albums dated only to a year on 1 July, for this comparison.
A5: Billboard 200 peak | B5: The album's peak on the main US albums chart (the Billboard 200 and its earlier names), not genre charts. Blank means it did not chart. Mostly from the 'US' column of Wikipedia discography tables, which cite Billboard.
A6: RIAA certification | B6: The highest US certification (Gold = 0.5 million units, Platinum = 1 million, n× Platinum = n million, Diamond = 10 million). 'RIAA units' converts the level into millions. Mostly from Wikipedia discography tables, which cite the RIAA database.
A7: Released in the US? | B7: 'yes' if the album charted on the Billboard 200 or another US Billboard chart (R&B, country, gospel, jazz), was RIAA-certified, or a source states a US release; 'no' if a source states it was not released there (coded by the original release, not later reissues); 'unknown' if no source says either way, which is not evidence that it wasn't released. Harrison counted only US albums; use this column to apply that rule.
A8: Grammy nominations | B8: From each act's page on grammy.com (the Recording Academy). 'Later' means at a ceremony after the act's Best New Artist ceremony; nominations in other categories at the same ceremony are listed separately and not counted as later. For groups, only nominations credited to the group count, not members' solo ones.
A9: Years active | B9: The years in which the act was making new studio albums: from the year of its first studio album to the year of its last, counting both, minus the years between a breakup and the reunion that ended it (counted only when both fall inside that span). 'After the ceremony' starts the count at the ceremony year. Solo acts have no breakups in the events file, so long quiet spells between their albums are not subtracted.
A10: Judgement calls | B10: Nominations count when grammy.com credits them to the act, including shared songwriting and collaboration nominations (for example Sade's 2002 Female Pop Vocal nomination, credited to Sade). Where an act's grammy.com page would not open (Rick Astley, Soul II Soul, Jody Watley, Jennifer Holliday), Wikipedia's awards table was used; for Simply Red and the Pretenders, band members' grammy.com pages listing nominations credited to the band. Each album's and act's source and any doubts are in the Source and Note columns.
A11: Source of the album list | B11: events_final.txt (the final events dataset): original studio albums only, dated by their first release anywhere.
A12: Built | B12: 29 October 2026. Values entered from research are in the Albums and Grammy nominations sheets; everything in Acts and Breaks is calculated.

Sheet Acts
A1: act_id | B1: Act | C1: Solo or group | D1: Best New Artist ceremony | E1: Ceremony year | F1: Best New Artist result | G1: Studio albums (all) | H1: Studio albums after the ceremony | I1: Studio albums released in the US | J1: Albums charted on the Billboard 200 (all) | K1: Albums charted after the ceremony | L1: First album year | M1: Last album year | N1: Best Billboard 200 peak (all) | O1: Best Billboard 200 peak after the ceremony | P1: Top-40 albums after the ceremony | Q1: RIAA-certified albums (all) | R1: RIAA-certified albums after the ceremony | S1: RIAA units, millions (all) | T1: RIAA units, millions, after the ceremony | U1: Later Grammy nominations | V1: Later Grammy wins | W1: Other nominations at the same ceremony | X1: Years active (all) | Y1: Years active after the ceremony | Z1: Note
A2: act_032 | B2: a-ha | C2: Group | D2: 31468 | E2: =YEAR(D2) -> 1986 | F2: nominated | G2: =COUNTIFS(Albums!$B$2:$B$406,B2) -> 11 | H2: =COUNTIFS(Albums!$B$2:$B$406,B2,Albums!$H$2:$H$406,"yes") -> 10 | I2: =COUNTIFS(Albums!$B$2:$B$406,B2,Albums!$I$2:$I$406,"yes") -> 4 | J2: =COUNTIFS(Albums!$B$2:$B$406,B2,Albums!$J$2:$J$406,">0") -> 3 | K2: =COUNTIFS(Albums!$B$2:$B$406,B2,Albums!$H$2:$H$406,"yes",Albums!$J$2:$J$406,">0") -> 2 | L2: =IF(G2=0,"",_xlfn.MINIFS(Albums!$E$2:$E$406,Albums!$B$2:$B$406,B2)) -> 1985 | M2: =IF(G2=0,"",_xlfn.MAXIFS(Albums!$E$2:$E$406,Albums!$B$2:$B$406,B2)) -> 2022 | N2: =IF(J2=0,"",_xlfn.MINIFS(Albums!$J$2:$J$406,Albums!$B$2:$B$406,B2,Albums!$J$2:$J$406,">0")) -> 15 | O2: =IF(K2=0,"",_xlfn.MINIFS(Albums!$J$2:$J$406,Albums!$B$2:$B$406,B2,Albums!$H$2:$H$406,"yes",Albums!$J$2:$J$406,">0")) -> 74 | P2: =COUNTIFS(Albums!$B$2:$B$406,B2,Albums!$H$2:$H$406,"yes",Albums!$J$2:$J$406,">0",Albums!$J$2:$J$406,"<=40") -> 0 | Q2: =COUNTIFS(Albums!$B$2:$B$406,B2,Albums!$M$2:$M$406,">0") -> 1 | R2: =COUNTIFS(Albums!$B$2:$B$406,B2,Albums!$H$2:$H$406,"yes",Albums!$M$2:$M$406,">0") -> 0 | S2: =SUMIFS(Albums!$M$2:$M$406,Albums!$B$2:$B$406,B2) -> 1 | T2: =SUMIFS(Albums!$M$2:$M$406,Albums!$B$2:$B$406,B2,Albums!$H$2:$H$406,"yes") -> 0 | U2: =COUNTIFS('Grammy nominations'!$A$2:$A$189,B2,'Grammy nominations'!$F$2:$F$189,"later") -> 0 | V2: =COUNTIFS('Grammy nominations'!$A$2:$A$189,B2,'Grammy nominations'!$F$2:$F$189,"later",'Grammy nominations'!$E$2:$E$189,"won") -> 0 | W2: =COUNTIFS('Grammy nominations'!$A$2:$A$189,B2,'Grammy nominations'!$F$2:$F$189,"same ceremony") -> 0 | X2: =IF(G2=0,"",M2-L2+1-SUMIFS(Breaks!$H$2:$H$31,Breaks!$A$2:$A$31,B2)) -> 30 | Y2: =IF(G2=0,"",IF(M2<E2,0,M2-MAX(L2,E2)+1-SUMIFS(Breaks!$H$2:$H$31,Breaks!$A$2:$A$31,B2,Breaks!$C$2:$C$31,">="&E2))) -> 29 | Z2: grammy.com lists 1 nomination (Best New Artist 1986), 0 wins
A3: act_012 | B3: Adam and the Ants | C3: Group | D3: 30006 | E3: =YEAR(D3) -> 1982 | F3: nominated | G3: =COUNTIFS(Albums!$B$2:$B$406,B3) -> 3 | H3: =COUNTIFS(Albums!$B$2:$B$406,B3,Albums!$H$2:$H$406,"yes") -> 0 | I3: =COUNTIFS(Albums!$B$2:$B$406,B3,Albums!$I$2:$I$406,"yes") -> 3 | J3: =COUNTIFS(Albums!$B$2:$B$406,B3,Albums!$J$2:$J$406,">0") -> 2 | K3: =COUNTIFS(Albums!$B$2:$B$406,B3,Albums!$H$2:$H$406,"yes",Albums!$J$2:$J$406,">0") -> 0 | L3: =IF(G3=0,"",_xlfn.MINIFS(Albums!$E$2:$E$406,Albums!$B$2:$B$406,B3)) -> 1979 | M3: =IF(G3=0,"",_xlfn.MAXIFS(Albums!$E$2:$E$406,Albums!$B$2:$B$406,B3)) -> 1981 | N3: =IF(J3=0,"",_xlfn.MINIFS(Albums!$J$2:$J$406,Albums!$B$2:$B$406,B3,Albums!$J$2:$J$406,">0")) -> 44 | O3: =IF(K3=0,"",_xlfn.MINIFS(Albums!$J$2:$J$406,Albums!$B$2:$B$406,B3,Albums!$H$2:$H$406,"yes",Albums!$J$2:$J$406,">0")) | P3: =COUNTIFS(Albums!$B$2:$B$406,B3,Albums!$H$2:$H$406,"yes",Albums!$J$2:$J$406,">0",Albums!$J$2:$J$406,"<=40") -> 0 | Q3: =COUNTIFS(Albums!$B$2:$B$406,B3,Albums!$M$2:$M$406,">0") -> 1 | R3: =COUNTIFS(Albums!$B$2:$B$406,B3,Albums!$H$2:$H$406,"yes",Albums!$M$2:$M$406,">0") -> 0 | S3: =SUMIFS(Albums!$M$2:$M$406,Albums!$B$2:$B$406,B3) -> 0.5 | T3: =SUMIFS(Albums!$M$2:$M$406,Albums!$B$2:$B$406,B3,Albums!$H$2:$H$406,"yes") -> 0 | U3: =COUNTIFS('Grammy nominations'!$A$2:$A$189,B3,'Grammy nominations'!$F$2:$F$189,"later") -> 0 | V3: =COUNTIFS('Grammy nominations'!$A$2:$A$189,B3,'Grammy nominations'!$F$2:$F$189,"later",'Grammy nominations'!$E$2:$E$189,"won") -> 0 | W3: =COUNTIFS('Grammy nominations'!$A$2:$A$189,B3,'Grammy nominations'!$F$2:$F$189,"same ceremony") -> 0 | X3: =IF(G3=0,"",M3-L3+1-SUMIFS(Breaks!$H$2:$H$31,Breaks!$A$2:$A$31,B3)) -> 3 | Y3: =IF(G3=0,"",IF(M3<E3,0,M3-MAX(L3,E3)+1-SUMIFS(Breaks!$H$2:$H$31,Breaks!$A$2:$A$31,B3,Breaks!$C$2:$C$31,">="&E3))) -> 0 | Z3: grammy.com lists 1 nomination (Best New Artist 1982), 0 wins; Adam Ant solo page excluded; Wikipedia band page lists only the same BNA nomination
A4: act_009 | B4: Amy Holland | C4: Solo | D4: 29642 | E4: =YEAR(D4) -> 1981 | F4: nominated | G4: =COUNTIFS(Albums!$B$2:$B$406,B4) -> 4 | H4: =COUNTIFS(Albums!$B$2:$B$406,B4,Albums!$H$2:$H$406,"yes") -> 3 | I4: =COUNTIFS(Albums!$B$2:$B$406,B4,Albums!$I$2:$I$406,"yes") -> 1 | J4: =COUNTIFS(Albums!$B$2:$B$406,B4,Albums!$J$2:$J$406,">0") -> 1 | K4: =COUNTIFS(Albums!$B$2:$B$406,B4,Albums!$H$2:$H$406,"yes",Albums!$J$2:$J$406,">0") -> 0 | L4: =IF(G4=0,"",_xlfn.MINIFS(Albums!$E$2:$E$406,Albums!$B$2:$B$406,B4)) -> 1980 | M4: =IF(G4=0,"",_xlfn.MAXIFS(Albums!$E$2:$E$406,Albums!$B$2:$B$406,B4)) -> 2016 | N4: =IF(J4=0,"",_xlfn.MINIFS(Albums!$J$2:$J$406,Albums!$B$2:$B$406,B4,Albums!$J$2:$J$406,">0")) -> 146 | O4: =IF(K4=0,"",_xlfn.MINIFS(Albums!$J$2:$J$406,Albums!$B$2:$B$406,B4,Albums!$H$2:$H$406,"yes",Albums!$J$2:$J$406,">0")) | P4: =COUNTIFS(Albums!$B$2:$B$406,B4,Albums!$H$2:$H$406,"yes",Albums!$J$2:$J$406,">0",Albums!$J$2:$J$406,"<=40") -> 0 | Q4: =COUNTIFS(Albums!$B$2:$B$406,B4,Albums!$M$2:$M$406,">0") -> 0 | R4: =COUNTIFS(Albums!$B$2:$B$406,B4,Albums!$H$2:$H$406,"yes",Albums!$M$2:$M$406,">0") -> 0 | S4: =SUMIFS(Albums!$M$2:$M$406,Albums!$B$2:$B$406,B4) -> 0 | T4: =SUMIFS(Albums!$M$2:$M$406,Albums!$B$2:$B$406,B4,Albums!$H$2:$H$406,"yes") -> 0 | U4: =COUNTIFS('Grammy nominations'!$A$2:$A$189,B4,'Grammy nominations'!$F$2:$F$189,"later") -> 0 | V4: =COUNTIFS('Grammy nominations'!$A$2:$A$189,B4,'Grammy nominations'!$F$2:$F$189,"later",'Grammy nominations'!$E$2:$E$189,"won") -> 0 | W4: =COUNTIFS('Grammy nominations'!$A$2:$A$189,B4,'Grammy nominations'!$F$2:$F$189,"same ceremony") -> 0 | X4: =IF(G4=0,"",M4-L4+1-SUMIFS(Breaks!$H$2:$H$31,Breaks!$A$2:$A$31,B4)) -> 37 | Y4: =IF(G4=0,"",IF(M4<E4,0,M4-MAX(L4,E4)+1-SUMIFS(Breaks!$H$2:$H$31,Breaks!$A$2:$A$31,B4,Breaks!$C$2:$C$31,">="&E4))) -> 36 | Z4: grammy.com lists only the Best New Artist nomination (1981).
A5: act_017 | B5: Asia | C5: Group | D5: 30370 | E5: =YEAR(D5) -> 1983 | F5: nominated | G5: =COUNTIFS(Albums!$B$2:$B$406,B5) -> 12 | H5: =COUNTIFS(Albums!$B$2:$B$406,B5,Albums!$H$2:$H$406,"yes") -> 11 | I5: =COUNTIFS(Albums!$B$2:$B$406,B5,Albums!$I$2:$I$406,"yes") -> 9 | J5: =COUNTIFS(Albums!$B$2:$B$406,B5,Albums!$J$2:$J$406,">0") -> 6 | K5: =COUNTIFS(Albums!$B$2:$B$406,B5,Albums!$H$2:$H$406,"yes",Albums!$J$2:$J$406,">0") -> 5 | L5: =IF(G5=0,"",_xlfn.MINIFS(Albums!$E$2:$E$406,Albums!$B$2:$B$406,B5)) -> 1982 | M5: =IF(G5=0,"",_xlfn.MAXIFS(Albums!$E$2:$E$406,Albums!$B$2:$B$406,B5)) -> 2014 | N5: =IF(J5=0,"",_xlfn.MINIFS(Albums!$J$2:$J$406,Albums!$B$2:$B$406,B5,Albums!$J$2:$J$406,">0")) -> 1 | O5: =IF(K5=0,"",_xlfn.MINIFS(Albums!$J$2:$J$406,Albums!$B$2:$B$406,B5,Albums!$H$2:$H$406,"yes",Albums!$J$2:$J$406,">0")) -> 6 | P5: =COUNTIFS(Albums!$B$2:$B$406,B5,Albums!$H$2:$H$406,"yes",Albums!$J$2:$J$406,">0",Albums!$J$2:$J$406,"<=40") -> 1 | Q5: =COUNTIFS(Albums!$B$2:$B$406,B5,Albums!$M$2:$M$406,">0") -> 2 | R5: =COUNTIFS(Albums!$B$2:$B$406,B5,Albums!$H$2:$H$406,"yes",Albums!$M$2:$M$406,">0") -> 1 | S5: =SUMIFS(Albums!$M$2:$M$406,Albums!$B$2:$B$406,B5) -> 5 | T5: =SUMIFS(Albums!$M$2:$M$406,Albums!$B$2:$B$406,B5,Albums!$H$2:$H$406,"yes") -> 1 | U5: =COUNTIFS('Grammy nominations'!$A$2:$A$189,B5,'Grammy nominations'!$F$2:$F$189,"later") -> 0 | V5: =COUNTIFS('Grammy nominations'!$A$2:$A$189,B5,'Grammy nominations'!$F$2:$F$189,"later",'Grammy nominations'!$E$2:$E$189,"won") -> 0 | W5: =COUNTIFS('Grammy nominations'!$A$2:$A$189,B5,'Grammy nominations'!$F$2:$F$189,"same ceremony") -> 1 | X5: =IF(G5=0,"",M5-L5+1-SUMIFS(Breaks!$H$2:$H$31,Breaks!$A$2:$A$31,B5)) -> 31 | Y5: =IF(G5=0,"",IF(M5<E5,0,M5-MAX(L5,E5)+1-SUMIFS(Breaks!$H$2:$H$31,Breaks!$A$2:$A$31,B5,Breaks!$C$2:$C$31,">="&E5))) -> 30 | Z5: grammy.com shows 2 nominations, 0 wins, both at the 25th ceremony (1983).
A6: act_022 | B6: Big Country | C6: Group | D6: 30740 | E6: =YEAR(D6) -> 1984 | F6: nominated | G6: =COUNTIFS(Albums!$B$2:$B$406,B6) -> 9 | H6: =COUNTIFS(Albums!$B$2:$B$406,B6,Albums!$H$2:$H$406,"yes") -> 8 | I6: =COUNTIFS(Albums!$B$2:$B$406,B6,Albums!$I$2:$I$406,"yes") -> 6 | J6: =COUNTIFS(Albums!$B$2:$B$406,B6,Albums!$J$2:$J$406,">0") -> 4 | K6: =COUNTIFS(Albums!$B$2:$B$406,B6,Albums!$H$2:$H$406,"yes",Albums!$J$2:$J$406,">0") -> 3 | L6: =IF(G6=0,"",_xlfn.MINIFS(Albums!$E$2:$E$406,Albums!$B$2:$B$406,B6)) -> 1983 | M6: =IF(G6=0,"",_xlfn.MAXIFS(Albums!$E$2:$E$406,Albums!$B$2:$B$406,B6)) -> 2013 | N6: =IF(J6=0,"",_xlfn.MINIFS(Albums!$J$2:$J$406,Albums!$B$2:$B$406,B6,Albums!$J$2:$J$406,">0")) -> 18 | O6: =IF(K6=0,"",_xlfn.MINIFS(Albums!$J$2:$J$406,Albums!$B$2:$B$406,B6,Albums!$H$2:$H$406,"yes",Albums!$J$2:$J$406,">0")) -> 59 | P6: =COUNTIFS(Albums!$B$2:$B$406,B6,Albums!$H$2:$H$406,"yes",Albums!$J$2:$J$406,">0",Albums!$J$2:$J$406,"<=40") -> 0 | Q6: =COUNTIFS(Albums!$B$2:$B$406,B6,Albums!$M$2:$M$406,">0") -> 1 | R6: =COUNTIFS(Albums!$B$2:$B$406,B6,Albums!$H$2:$H$406,"yes",Albums!$M$2:$M$406,">0") -> 0 | S6: =SUMIFS(Albums!$M$2:$M$406,Albums!$B$2:$B$406,B6) -> 0.5 | T6: =SUMIFS(Albums!$M$2:$M$406,Albums!$B$2:$B$406,B6,Albums!$H$2:$H$406,"yes") -> 0 | U6: =COUNTIFS('Grammy nominations'!$A$2:$A$189,B6,'Grammy nominations'!$F$2:$F$189,"later") -> 0 | V6: =COUNTIFS('Grammy nominations'!$A$2:$A$189,B6,'Grammy nominations'!$F$2:$F$189,"later",'Grammy nominations'!$E$2:$E$189,"won") -> 0 | W6: =COUNTIFS('Grammy nominations'!$A$2:$A$189,B6,'Grammy nominations'!$F$2:$F$189,"same ceremony") -> 1 | X6: =IF(G6=0,"",M6-L6+1-SUMIFS(Breaks!$H$2:$H$31,Breaks!$A$2:$A$31,B6)) -> 23 | Y6: =IF(G6=0,"",IF(M6<E6,0,M6-MAX(L6,E6)+1-SUMIFS(Breaks!$H$2:$H$31,Breaks!$A$2:$A$31,B6,Breaks!$C$2:$C$31,">="&E6))) -> 22 | Z6: grammy.com lists 2 nominations, both at 1984 ceremony, 0 wins
A7: act_042 | B7: Breakfast Club | C7: Group | D7: 32204 | E7: =YEAR(D7) -> 1988 | F7: nominated | G7: =COUNTIFS(Albums!$B$2:$B$406,B7) -> 1 | H7: =COUNTIFS(Albums!$B$2:$B$406,B7,Albums!$H$2:$H$406,"yes") -> 0 | I7: =COUNTIFS(Albums!$B$2:$B$406,B7,Albums!$I$2:$I$406,"yes") -> 1 | J7: =COUNTIFS(Albums!$B$2:$B$406,B7,Albums!$J$2:$J$406,">0") -> 1 | K7: =COUNTIFS(Albums!$B$2:$B$406,B7,Albums!$H$2:$H$406,"yes",Albums!$J$2:$J$406,">0") -> 0 | L7: =IF(G7=0,"",_xlfn.MINIFS(Albums!$E$2:$E$406,Albums!$B$2:$B$406,B7)) -> 1987 | M7: =IF(G7=0,"",_xlfn.MAXIFS(Albums!$E$2:$E$406,Albums!$B$2:$B$406,B7)) -> 1987 | N7: =IF(J7=0,"",_xlfn.MINIFS(Albums!$J$2:$J$406,Albums!$B$2:$B$406,B7,Albums!$J$2:$J$406,">0")) -> 43 | O7: =IF(K7=0,"",_xlfn.MINIFS(Albums!$J$2:$J$406,Albums!$B$2:$B$406,B7,Albums!$H$2:$H$406,"yes",Albums!$J$2:$J$406,">0")) | P7: =COUNTIFS(Albums!$B$2:$B$406,B7,Albums!$H$2:$H$406,"yes",Albums!$J$2:$J$406,">0",Albums!$J$2:$J$406,"<=40") -> 0 | Q7: =COUNTIFS(Albums!$B$2:$B$406,B7,Albums!$M$2:$M$406,">0") -> 0 | R7: =COUNTIFS(Albums!$B$2:$B$406,B7,Albums!$H$2:$H$406,"yes",Albums!$M$2:$M$406,">0") -> 0 | S7: =SUMIFS(Albums!$M$2:$M$406,Albums!$B$2:$B$406,B7) -> 0 | T7: =SUMIFS(Albums!$M$2:$M$406,Albums!$B$2:$B$406,B7,Albums!$H$2:$H$406,"yes") -> 0 | U7: =COUNTIFS('Grammy nominations'!$A$2:$A$189,B7,'Grammy nominations'!$F$2:$F$189,"later") -> 0 | V7: =COUNTIFS('Grammy nominations'!$A$2:$A$189,B7,'Grammy nominations'!$F$2:$F$189,"later",'Grammy nominations'!$E$2:$E$189,"won") -> 0 | W7: =COUNTIFS('Grammy nominations'!$A$2:$A$189,B7,'Grammy nominations'!$F$2:$F$189,"same ceremony") -> 0 | X7: =IF(G7=0,"",M7-L7+1-SUMIFS(Breaks!$H$2:$H$31,Breaks!$A$2:$A$31,B7)) -> 1 | Y7: =IF(G7=0,"",IF(M7<E7,0,M7-MAX(L7,E7)+1-SUMIFS(Breaks!$H$2:$H$31,Breaks!$A$2:$A$31,B7,Breaks!$C$2:$C$31,">="&E7))) -> 0 | Z7: grammy.com lists a single entry: Best New Artist, 1988 (30th), nominated. 0 wins, 1 nomination.
A8: act_036 | B8: Bruce Hornsby and the Range | C8: Group | D8: 31832 | E8: =YEAR(D8) -> 1987 | F8: won | G8: =COUNTIFS(Albums!$B$2:$B$406,B8) -> 3 | H8: =COUNTIFS(Albums!$B$2:$B$406,B8,Albums!$H$2:$H$406,"yes") -> 2 | I8: =COUNTIFS(Albums!$B$2:$B$406,B8,Albums!$I$2:$I$406,"yes") -> 3 | J8: =COUNTIFS(Albums!$B$2:$B$406,B8,Albums!$J$2:$J$406,">0") -> 3 | K8: =COUNTIFS(Albums!$B$2:$B$406,B8,Albums!$H$2:$H$406,"yes",Albums!$J$2:$J$406,">0") -> 2 | L8: =IF(G8=0,"",_xlfn.MINIFS(Albums!$E$2:$E$406,Albums!$B$2:$B$406,B8)) -> 1986 | M8: =IF(G8=0,"",_xlfn.MAXIFS(Albums!$E$2:$E$406,Albums!$B$2:$B$406,B8)) -> 1990 | N8: =IF(J8=0,"",_xlfn.MINIFS(Albums!$J$2:$J$406,Albums!$B$2:$B$406,B8,Albums!$J$2:$J$406,">0")) -> 3 | O8: =IF(K8=0,"",_xlfn.MINIFS(Albums!$J$2:$J$406,Albums!$B$2:$B$406,B8,Albums!$H$2:$H$406,"yes",Albums!$J$2:$J$406,">0")) -> 5 | P8: =COUNTIFS(Albums!$B$2:$B$406,B8,Albums!$H$2:$H$406,"yes",Albums!$J$2:$J$406,">0",Albums!$J$2:$J$406,"<=40") -> 2 | Q8: =COUNTIFS(Albums!$B$2:$B$406,B8,Albums!$M$2:$M$406,">0") -> 3 | R8: =COUNTIFS(Albums!$B$2:$B$406,B8,Albums!$H$2:$H$406,"yes",Albums!$M$2:$M$406,">0") -> 2 | S8: =SUMIFS(Albums!$M$2:$M$406,Albums!$B$2:$B$406,B8) -> 4.5 | T8: =SUMIFS(Albums!$M$2:$M$406,Albums!$B$2:$B$406,B8,Albums!$H$2:$H$406,"yes") -> 1.5 | U8: =COUNTIFS('Grammy nominations'!$A$2:$A$189,B8,'Grammy nominations'!$F$2:$F$189,"later") -> 1 | V8: =COUNTIFS('Grammy nominations'!$A$2:$A$189,B8,'Grammy nominations'!$F$2:$F$189,"later",'Grammy nominations'!$E$2:$E$189,"won") -> 0 | W8: =COUNTIFS('Grammy nominations'!$A$2:$A$189,B8,'Grammy nominations'!$F$2:$F$189,"same ceremony") -> 0 | X8: =IF(G8=0,"",M8-L8+1-SUMIFS(Breaks!$H$2:$H$31,Breaks!$A$2:$A$31,B8)) -> 5 | Y8: =IF(G8=0,"",IF(M8<E8,0,M8-MAX(L8,E8)+1-SUMIFS(Breaks!$H$2:$H$31,Breaks!$A$2:$A$31,B8,Breaks!$C$2:$C$31,">="&E8))) -> 4 | Z8: grammy.com 'Bruce Hornsby And The Range' page shows 2 nominations / 1 win: 1987 Best New Artist (won) and 1991 Across The River. Bruce Hornsby solo nominations excluded per instructions.
A9: act_006 | B9: Christopher Cross | C9: Solo | D9: 29642 | E9: =YEAR(D9) -> 1981 | F9: won | G9: =COUNTIFS(Albums!$B$2:$B$406,B9) -> 11 | H9: =COUNTIFS(Albums!$B$2:$B$406,B9,Albums!$H$2:$H$406,"yes") -> 10 | I9: =COUNTIFS(Albums!$B$2:$B$406,B9,Albums!$I$2:$I$406,"yes") -> 5 | J9: =COUNTIFS(Albums!$B$2:$B$406,B9,Albums!$J$2:$J$406,">0") -> 3 | K9: =COUNTIFS(Albums!$B$2:$B$406,B9,Albums!$H$2:$H$406,"yes",Albums!$J$2:$J$406,">0") -> 2 | L9: =IF(G9=0,"",_xlfn.MINIFS(Albums!$E$2:$E$406,Albums!$B$2:$B$406,B9)) -> 1979 | M9: =IF(G9=0,"",_xlfn.MAXIFS(Albums!$E$2:$E$406,Albums!$B$2:$B$406,B9)) -> 2017 | N9: =IF(J9=0,"",_xlfn.MINIFS(Albums!$J$2:$J$406,Albums!$B$2:$B$406,B9,Albums!$J$2:$J$406,">0")) -> 6 | O9: =IF(K9=0,"",_xlfn.MINIFS(Albums!$J$2:$J$406,Albums!$B$2:$B$406,B9,Albums!$H$2:$H$406,"yes",Albums!$J$2:$J$406,">0")) -> 11 | P9: =COUNTIFS(Albums!$B$2:$B$406,B9,Albums!$H$2:$H$406,"yes",Albums!$J$2:$J$406,">0",Albums!$J$2:$J$406,"<=40") -> 1 | Q9: =COUNTIFS(Albums!$B$2:$B$406,B9,Albums!$M$2:$M$406,">0") -> 2 | R9: =COUNTIFS(Albums!$B$2:$B$406,B9,Albums!$H$2:$H$406,"yes",Albums!$M$2:$M$406,">0") -> 1 | S9: =SUMIFS(Albums!$M$2:$M$406,Albums!$B$2:$B$406,B9) -> 5.5 | T9: =SUMIFS(Albums!$M$2:$M$406,Albums!$B$2:$B$406,B9,Albums!$H$2:$H$406,"yes") -> 0.5 | U9: =COUNTIFS('Grammy nominations'!$A$2:$A$189,B9,'Grammy nominations'!$F$2:$F$189,"later") -> 3 | V9: =COUNTIFS('Grammy nominations'!$A$2:$A$189,B9,'Grammy nominations'!$F$2:$F$189,"later",'Grammy nominations'!$E$2:$E$189,"won") -> 0 | W9: =COUNTIFS('Grammy nominations'!$A$2:$A$189,B9,'Grammy nominations'!$F$2:$F$189,"same ceremony") -> 5 | X9: =IF(G9=0,"",M9-L9+1-SUMIFS(Breaks!$H$2:$H$31,Breaks!$A$2:$A$31,B9)) -> 39 | Y9: =IF(G9=0,"",IF(M9<E9,0,M9-MAX(L9,E9)+1-SUMIFS(Breaks!$H$2:$H$31,Breaks!$A$2:$A$31,B9,Breaks!$C$2:$C$31,">="&E9))) -> 37 | Z9: grammy.com: 5 wins, 9 nominations (incl. BNA 1981 win)
A10: act_029 | B10: Corey Hart | C10: Solo | D10: 31104 | E10: =YEAR(D10) -> 1985 | F10: nominated | G10: =COUNTIFS(Albums!$B$2:$B$406,B10) -> 8 | H10: =COUNTIFS(Albums!$B$2:$B$406,B10,Albums!$H$2:$H$406,"yes") -> 7 | I10: =COUNTIFS(Albums!$B$2:$B$406,B10,Albums!$I$2:$I$406,"yes") -> 5 | J10: =COUNTIFS(Albums!$B$2:$B$406,B10,Albums!$J$2:$J$406,">0") -> 5 | K10: =COUNTIFS(Albums!$B$2:$B$406,B10,Albums!$H$2:$H$406,"yes",Albums!$J$2:$J$406,">0") -> 4 | L10: =IF(G10=0,"",_xlfn.MINIFS(Albums!$E$2:$E$406,Albums!$B$2:$B$406,B10)) -> 1983 | M10: =IF(G10=0,"",_xlfn.MAXIFS(Albums!$E$2:$E$406,Albums!$B$2:$B$406,B10)) -> 1998 | N10: =IF(J10=0,"",_xlfn.MINIFS(Albums!$J$2:$J$406,Albums!$B$2:$B$406,B10,Albums!$J$2:$J$406,">0")) -> 20 | O10: =IF(K10=0,"",_xlfn.MINIFS(Albums!$J$2:$J$406,Albums!$B$2:$B$406,B10,Albums!$H$2:$H$406,"yes",Albums!$J$2:$J$406,">0")) -> 20 | P10: =COUNTIFS(Albums!$B$2:$B$406,B10,Albums!$H$2:$H$406,"yes",Albums!$J$2:$J$406,">0",Albums!$J$2:$J$406,"<=40") -> 1 | Q10: =COUNTIFS(Albums!$B$2:$B$406,B10,Albums!$M$2:$M$406,">0") -> 3 | R10: =COUNTIFS(Albums!$B$2:$B$406,B10,Albums!$H$2:$H$406,"yes",Albums!$M$2:$M$406,">0") -> 2 | S10: =SUMIFS(Albums!$M$2:$M$406,Albums!$B$2:$B$406,B10) -> 1.5 | T10: =SUMIFS(Albums!$M$2:$M$406,Albums!$B$2:$B$406,B10,Albums!$H$2:$H$406,"yes") -> 1 | U10: =COUNTIFS('Grammy nominations'!$A$2:$A$189,B10,'Grammy nominations'!$F$2:$F$189,"later") -> 0 | V10: =COUNTIFS('Grammy nominations'!$A$2:$A$189,B10,'Grammy nominations'!$F$2:$F$189,"later",'Grammy nominations'!$E$2:$E$189,"won") -> 0 | W10: =COUNTIFS('Grammy nominations'!$A$2:$A$189,B10,'Grammy nominations'!$F$2:$F$189,"same ceremony") -> 0 | X10: =IF(G10=0,"",M10-L10+1-SUMIFS(Breaks!$H$2:$H$31,Breaks!$A$2:$A$31,B10)) -> 16 | Y10: =IF(G10=0,"",IF(M10<E10,0,M10-MAX(L10,E10)+1-SUMIFS(Breaks!$H$2:$H$31,Breaks!$A$2:$A$31,B10,Breaks!$C$2:$C$31,">="&E10))) -> 14 | Z10: grammy.com shows 1 nomination (Best New Artist, 27th, 1985), 0 wins.
A11: act_021 | B11: Culture Club | C11: Group | D11: 30740 | E11: =YEAR(D11) -> 1984 | F11: won | G11: =COUNTIFS(Albums!$B$2:$B$406,B11) -> 6 | H11: =COUNTIFS(Albums!$B$2:$B$406,B11,Albums!$H$2:$H$406,"yes") -> 4 | I11: =COUNTIFS(Albums!$B$2:$B$406,B11,Albums!$I$2:$I$406,"yes") -> 4 | J11: =COUNTIFS(Albums!$B$2:$B$406,B11,Albums!$J$2:$J$406,">0") -> 4 | K11: =COUNTIFS(Albums!$B$2:$B$406,B11,Albums!$H$2:$H$406,"yes",Albums!$J$2:$J$406,">0") -> 2 | L11: =IF(G11=0,"",_xlfn.MINIFS(Albums!$E$2:$E$406,Albums!$B$2:$B$406,B11)) -> 1982 | M11: =IF(G11=0,"",_xlfn.MAXIFS(Albums!$E$2:$E$406,Albums!$B$2:$B$406,B11)) -> 2018 | N11: =IF(J11=0,"",_xlfn.MINIFS(Albums!$J$2:$J$406,Albums!$B$2:$B$406,B11,Albums!$J$2:$J$406,">0")) -> 2 | O11: =IF(K11=0,"",_xlfn.MINIFS(Albums!$J$2:$J$406,Albums!$B$2:$B$406,B11,Albums!$H$2:$H$406,"yes",Albums!$J$2:$J$406,">0")) -> 26 | P11: =COUNTIFS(Albums!$B$2:$B$406,B11,Albums!$H$2:$H$406,"yes",Albums!$J$2:$J$406,">0",Albums!$J$2:$J$406,"<=40") -> 2 | Q11: =COUNTIFS(Albums!$B$2:$B$406,B11,Albums!$M$2:$M$406,">0") -> 3 | R11: =COUNTIFS(Albums!$B$2:$B$406,B11,Albums!$H$2:$H$406,"yes",Albums!$M$2:$M$406,">0") -> 1 | S11: =SUMIFS(Albums!$M$2:$M$406,Albums!$B$2:$B$406,B11) -> 6 | T11: =SUMIFS(Albums!$M$2:$M$406,Albums!$B$2:$B$406,B11,Albums!$H$2:$H$406,"yes") -> 1 | U11: =COUNTIFS('Grammy nominations'!$A$2:$A$189,B11,'Grammy nominations'!$F$2:$F$189,"later") -> 0 | V11: =COUNTIFS('Grammy nominations'!$A$2:$A$189,B11,'Grammy nominations'!$F$2:$F$189,"later",'Grammy nominations'!$E$2:$E$189,"won") -> 0 | W11: =COUNTIFS('Grammy nominations'!$A$2:$A$189,B11,'Grammy nominations'!$F$2:$F$189,"same ceremony") -> 1 | X11: =IF(G11=0,"",M11-L11+1-SUMIFS(Breaks!$H$2:$H$31,Breaks!$A$2:$A$31,B11)) -> 15 | Y11: =IF(G11=0,"",IF(M11<E11,0,M11-MAX(L11,E11)+1-SUMIFS(Breaks!$H$2:$H$31,Breaks!$A$2:$A$31,B11,Breaks!$C$2:$C$31,">="&E11))) -> 13 | Z11: grammy.com shows 2 nominations / 1 win, both at the 1984 ceremony (Best New Artist won; Do You Really Want To Hurt Me nominated).
A12: act_043 | B12: Cutting Crew | C12: Group | D12: 32204 | E12: =YEAR(D12) -> 1988 | F12: nominated | G12: =COUNTIFS(Albums!$B$2:$B$406,B12) -> 5 | H12: =COUNTIFS(Albums!$B$2:$B$406,B12,Albums!$H$2:$H$406,"yes") -> 4 | I12: =COUNTIFS(Albums!$B$2:$B$406,B12,Albums!$I$2:$I$406,"yes") -> 2 | J12: =COUNTIFS(Albums!$B$2:$B$406,B12,Albums!$J$2:$J$406,">0") -> 2 | K12: =COUNTIFS(Albums!$B$2:$B$406,B12,Albums!$H$2:$H$406,"yes",Albums!$J$2:$J$406,">0") -> 1 | L12: =IF(G12=0,"",_xlfn.MINIFS(Albums!$E$2:$E$406,Albums!$B$2:$B$406,B12)) -> 1986 | M12: =IF(G12=0,"",_xlfn.MAXIFS(Albums!$E$2:$E$406,Albums!$B$2:$B$406,B12)) -> 2015 | N12: =IF(J12=0,"",_xlfn.MINIFS(Albums!$J$2:$J$406,Albums!$B$2:$B$406,B12,Albums!$J$2:$J$406,">0")) -> 16 | O12: =IF(K12=0,"",_xlfn.MINIFS(Albums!$J$2:$J$406,Albums!$B$2:$B$406,B12,Albums!$H$2:$H$406,"yes",Albums!$J$2:$J$406,">0")) -> 150 | P12: =COUNTIFS(Albums!$B$2:$B$406,B12,Albums!$H$2:$H$406,"yes",Albums!$J$2:$J$406,">0",Albums!$J$2:$J$406,"<=40") -> 0 | Q12: =COUNTIFS(Albums!$B$2:$B$406,B12,Albums!$M$2:$M$406,">0") -> 1 | R12: =COUNTIFS(Albums!$B$2:$B$406,B12,Albums!$H$2:$H$406,"yes",Albums!$M$2:$M$406,">0") -> 0 | S12: =SUMIFS(Albums!$M$2:$M$406,Albums!$B$2:$B$406,B12) -> 0.5 | T12: =SUMIFS(Albums!$M$2:$M$406,Albums!$B$2:$B$406,B12,Albums!$H$2:$H$406,"yes") -> 0 | U12: =COUNTIFS('Grammy nominations'!$A$2:$A$189,B12,'Grammy nominations'!$F$2:$F$189,"later") -> 0 | V12: =COUNTIFS('Grammy nominations'!$A$2:$A$189,B12,'Grammy nominations'!$F$2:$F$189,"later",'Grammy nominations'!$E$2:$E$189,"won") -> 0 | W12: =COUNTIFS('Grammy nominations'!$A$2:$A$189,B12,'Grammy nominations'!$F$2:$F$189,"same ceremony") -> 0 | X12: =IF(G12=0,"",M12-L12+1-SUMIFS(Breaks!$H$2:$H$31,Breaks!$A$2:$A$31,B12)) -> 30 | Y12: =IF(G12=0,"",IF(M12<E12,0,M12-MAX(L12,E12)+1-SUMIFS(Breaks!$H$2:$H$31,Breaks!$A$2:$A$31,B12,Breaks!$C$2:$C$31,">="&E12))) -> 28 | Z12: grammy.com lists 1 nomination (Best New Artist 1988), 0 wins; Wikipedia band page says one nomination (Best New Artist)
A13: act_026 | B13: Cyndi Lauper | C13: Solo | D13: 31104 | E13: =YEAR(D13) -> 1985 | F13: won | G13: =COUNTIFS(Albums!$B$2:$B$406,B13) -> 11 | H13: =COUNTIFS(Albums!$B$2:$B$406,B13,Albums!$H$2:$H$406,"yes") -> 10 | I13: =COUNTIFS(Albums!$B$2:$B$406,B13,Albums!$I$2:$I$406,"yes") -> 10 | J13: =COUNTIFS(Albums!$B$2:$B$406,B13,Albums!$J$2:$J$406,">0") -> 9 | K13: =COUNTIFS(Albums!$B$2:$B$406,B13,Albums!$H$2:$H$406,"yes",Albums!$J$2:$J$406,">0") -> 8 | L13: =IF(G13=0,"",_xlfn.MINIFS(Albums!$E$2:$E$406,Albums!$B$2:$B$406,B13)) -> 1983 | M13: =IF(G13=0,"",_xlfn.MAXIFS(Albums!$E$2:$E$406,Albums!$B$2:$B$406,B13)) -> 2016 | N13: =IF(J13=0,"",_xlfn.MINIFS(Albums!$J$2:$J$406,Albums!$B$2:$B$406,B13,Albums!$J$2:$J$406,">0")) -> 4 | O13: =IF(K13=0,"",_xlfn.MINIFS(Albums!$J$2:$J$406,Albums!$B$2:$B$406,B13,Albums!$H$2:$H$406,"yes",Albums!$J$2:$J$406,">0")) -> 4 | P13: =COUNTIFS(Albums!$B$2:$B$406,B13,Albums!$H$2:$H$406,"yes",Albums!$J$2:$J$406,">0",Albums!$J$2:$J$406,"<=40") -> 5 | Q13: =COUNTIFS(Albums!$B$2:$B$406,B13,Albums!$M$2:$M$406,">0") -> 2 | R13: =COUNTIFS(Albums!$B$2:$B$406,B13,Albums!$H$2:$H$406,"yes",Albums!$M$2:$M$406,">0") -> 1 | S13: =SUMIFS(Albums!$M$2:$M$406,Albums!$B$2:$B$406,B13) -> 9 | T13: =SUMIFS(Albums!$M$2:$M$406,Albums!$B$2:$B$406,B13,Albums!$H$2:$H$406,"yes") -> 2 | U13: =COUNTIFS('Grammy nominations'!$A$2:$A$189,B13,'Grammy nominations'!$F$2:$F$189,"later") -> 11 | V13: =COUNTIFS('Grammy nominations'!$A$2:$A$189,B13,'Grammy nominations'!$F$2:$F$189,"later",'Grammy nominations'!$E$2:$E$189,"won") -> 1 | W13: =COUNTIFS('Grammy nominations'!$A$2:$A$189,B13,'Grammy nominations'!$F$2:$F$189,"same ceremony") -> 4 | X13: =IF(G13=0,"",M13-L13+1-SUMIFS(Breaks!$H$2:$H$31,Breaks!$A$2:$A$31,B13)) -> 34 | Y13: =IF(G13=0,"",IF(M13<E13,0,M13-MAX(L13,E13)+1-SUMIFS(Breaks!$H$2:$H$31,Breaks!$A$2:$A$31,B13,Breaks!$C$2:$C$31,">="&E13))) -> 32 | Z13: grammy.com shows 16 nominations, 2 wins (Best New Artist 1985 and Best Musical Theater Album 2014 for Kinky Boots); the 2017 Kinky Boots entry is labelled Nominee on grammy.com. The 2005 arrangement nomination is listed on her grammy.com page although the category honours the arranger.
... A40: act_031 | B40: Sade | C40: Group | D40: 31468 | E40: =YEAR(D40) -> 1986 | F40: won | G40: =COUNTIFS(Albums!$B$2:$B$406,B40) -> 6 | H40: =COUNTIFS(Albums!$B$2:$B$406,B40,Albums!$H$2:$H$406,"yes") -> 4 | I40: =COUNTIFS(Albums!$B$2:$B$406,B40,Albums!$I$2:$I$406,"yes") -> 6 | J40: =COUNTIFS(Albums!$B$2:$B$406,B40,Albums!$J$2:$J$406,">0") -> 6 | K40: =COUNTIFS(Albums!$B$2:$B$406,B40,Albums!$H$2:$H$406,"yes",Albums!$J$2:$J$406,">0") -> 4 | L40: =IF(G40=0,"",_xlfn.MINIFS(Albums!$E$2:$E$406,Albums!$B$2:$B$406,B40)) -> 1984 | M40: =IF(G40=0,"",_xlfn.MAXIFS(Albums!$E$2:$E$406,Albums!$B$2:$B$406,B40)) -> 2010 | N40: =IF(J40=0,"",_xlfn.MINIFS(Albums!$J$2:$J$406,Albums!$B$2:$B$406,B40,Albums!$J$2:$J$406,">0")) -> 1 | O40: =IF(K40=0,"",_xlfn.MINIFS(Albums!$J$2:$J$406,Albums!$B$2:$B$406,B40,Albums!$H$2:$H$406,"yes",Albums!$J$2:$J$406,">0")) -> 1 | P40: =COUNTIFS(Albums!$B$2:$B$406,B40,Albums!$H$2:$H$406,"yes",Albums!$J$2:$J$406,">0",Albums!$J$2:$J$406,"<=40") -> 4 | Q40: =COUNTIFS(Albums!$B$2:$B$406,B40,Albums!$M$2:$M$406,">0") -> 6 | R40: =COUNTIFS(Albums!$B$2:$B$406,B40,Albums!$H$2:$H$406,"yes",Albums!$M$2:$M$406,">0") -> 4 | S40: =SUMIFS(Albums!$M$2:$M$406,Albums!$B$2:$B$406,B40) -> 19 | T40: =SUMIFS(Albums!$M$2:$M$406,Albums!$B$2:$B$406,B40,Albums!$H$2:$H$406,"yes") -> 11 | U40: =COUNTIFS('Grammy nominations'!$A$2:$A$189,B40,'Grammy nominations'!$F$2:$F$189,"later") -> 8 | V40: =COUNTIFS('Grammy nominations'!$A$2:$A$189,B40,'Grammy nominations'!$F$2:$F$189,"later",'Grammy nominations'!$E$2:$E$189,"won") -> 3 | W40: =COUNTIFS('Grammy nominations'!$A$2:$A$189,B40,'Grammy nominations'!$F$2:$F$189,"same ceremony") -> 0 | X40: =IF(G40=0,"",M40-L40+1-SUMIFS(Breaks!$H$2:$H$31,Breaks!$A$2:$A$31,B40)) -> 27 | Y40: =IF(G40=0,"",IF(M40<E40,0,M40-MAX(L40,E40)+1-SUMIFS(Breaks!$H$2:$H$31,Breaks!$A$2:$A$31,B40,Breaks!$C$2:$C$31,">="&E40))) -> 25 | Z40: grammy.com 'Sade' act page (8051): 9 entries, 4 wins, Best New Artist 1986 won. The 2002 Best Female Pop Vocal Performance ('By Your Side') is a female solo category but grammy.com credits it to 'Sade' on this act page, so it is kept; drop it if a strict group-only count is wanted. Excluded: 2026 Best Music Video nomination for 'Young Lion', which grammy.com credits to 'Sade Adu' (the singer, solo), per https://www.grammy.com/awards/categories/best-music-video/2026/ and https://www.grammy.com/artists/sade-adu/1247.
A41: act_011 | B41: Sheena Easton | C41: Solo | D41: 30006 | E41: =YEAR(D41) -> 1982 | F41: won | G41: =COUNTIFS(Albums!$B$2:$B$406,B41) -> 14 | H41: =COUNTIFS(Albums!$B$2:$B$406,B41,Albums!$H$2:$H$406,"yes") -> 12 | I41: =COUNTIFS(Albums!$B$2:$B$406,B41,Albums!$I$2:$I$406,"yes") -> 8 | J41: =COUNTIFS(Albums!$B$2:$B$406,B41,Albums!$J$2:$J$406,">0") -> 8 | K41: =COUNTIFS(Albums!$B$2:$B$406,B41,Albums!$H$2:$H$406,"yes",Albums!$J$2:$J$406,">0") -> 6 | L41: =IF(G41=0,"",_xlfn.MINIFS(Albums!$E$2:$E$406,Albums!$B$2:$B$406,B41)) -> 1981 | M41: =IF(G41=0,"",_xlfn.MAXIFS(Albums!$E$2:$E$406,Albums!$B$2:$B$406,B41)) -> 2000 | N41: =IF(J41=0,"",_xlfn.MINIFS(Albums!$J$2:$J$406,Albums!$B$2:$B$406,B41,Albums!$J$2:$J$406,">0")) -> 15 | O41: =IF(K41=0,"",_xlfn.MINIFS(Albums!$J$2:$J$406,Albums!$B$2:$B$406,B41,Albums!$H$2:$H$406,"yes",Albums!$J$2:$J$406,">0")) -> 15 | P41: =COUNTIFS(Albums!$B$2:$B$406,B41,Albums!$H$2:$H$406,"yes",Albums!$J$2:$J$406,">0",Albums!$J$2:$J$406,"<=40") -> 3 | Q41: =COUNTIFS(Albums!$B$2:$B$406,B41,Albums!$M$2:$M$406,">0") -> 5 | R41: =COUNTIFS(Albums!$B$2:$B$406,B41,Albums!$H$2:$H$406,"yes",Albums!$M$2:$M$406,">0") -> 3 | S41: =SUMIFS(Albums!$M$2:$M$406,Albums!$B$2:$B$406,B41) -> 3 | T41: =SUMIFS(Albums!$M$2:$M$406,Albums!$B$2:$B$406,B41,Albums!$H$2:$H$406,"yes") -> 2 | U41: =COUNTIFS('Grammy nominations'!$A$2:$A$189,B41,'Grammy nominations'!$F$2:$F$189,"later") -> 4 | V41: =COUNTIFS('Grammy nominations'!$A$2:$A$189,B41,'Grammy nominations'!$F$2:$F$189,"later",'Grammy nominations'!$E$2:$E$189,"won") -> 1 | W41: =COUNTIFS('Grammy nominations'!$A$2:$A$189,B41,'Grammy nominations'!$F$2:$F$189,"same ceremony") -> 1 | X41: =IF(G41=0,"",M41-L41+1-SUMIFS(Breaks!$H$2:$H$31,Breaks!$A$2:$A$31,B41)) -> 20 | Y41: =IF(G41=0,"",IF(M41<E41,0,M41-MAX(L41,E41)+1-SUMIFS(Breaks!$H$2:$H$31,Breaks!$A$2:$A$31,B41,Breaks!$C$2:$C$31,">="&E41))) -> 19
A42: act_027 | B42: Sheila E. | C42: Solo | D42: 31104 | E42: =YEAR(D42) -> 1985 | F42: nominated | G42: =COUNTIFS(Albums!$B$2:$B$406,B42) -> 10 | H42: =COUNTIFS(Albums!$B$2:$B$406,B42,Albums!$H$2:$H$406,"yes") -> 9 | I42: =COUNTIFS(Albums!$B$2:$B$406,B42,Albums!$I$2:$I$406,"yes") -> 4 | J42: =COUNTIFS(Albums!$B$2:$B$406,B42,Albums!$J$2:$J$406,">0") -> 4 | K42: =COUNTIFS(Albums!$B$2:$B$406,B42,Albums!$H$2:$H$406,"yes",Albums!$J$2:$J$406,">0") -> 3 | L42: =IF(G42=0,"",_xlfn.MINIFS(Albums!$E$2:$E$406,Albums!$B$2:$B$406,B42)) -> 1984 | M42: =IF(G42=0,"",_xlfn.MAXIFS(Albums!$E$2:$E$406,Albums!$B$2:$B$406,B42)) -> 2024 | N42: =IF(J42=0,"",_xlfn.MINIFS(Albums!$J$2:$J$406,Albums!$B$2:$B$406,B42,Albums!$J$2:$J$406,">0")) -> 28 | O42: =IF(K42=0,"",_xlfn.MINIFS(Albums!$J$2:$J$406,Albums!$B$2:$B$406,B42,Albums!$H$2:$H$406,"yes",Albums!$J$2:$J$406,">0")) -> 50 | P42: =COUNTIFS(Albums!$B$2:$B$406,B42,Albums!$H$2:$H$406,"yes",Albums!$J$2:$J$406,">0",Albums!$J$2:$J$406,"<=40") -> 0 | Q42: =COUNTIFS(Albums!$B$2:$B$406,B42,Albums!$M$2:$M$406,">0") -> 2 | R42: =COUNTIFS(Albums!$B$2:$B$406,B42,Albums!$H$2:$H$406,"yes",Albums!$M$2:$M$406,">0") -> 1 | S42: =SUMIFS(Albums!$M$2:$M$406,Albums!$B$2:$B$406,B42) -> 1 | T42: =SUMIFS(Albums!$M$2:$M$406,Albums!$B$2:$B$406,B42,Albums!$H$2:$H$406,"yes") -> 0.5 | U42: =COUNTIFS('Grammy nominations'!$A$2:$A$189,B42,'Grammy nominations'!$F$2:$F$189,"later") -> 2 | V42: =COUNTIFS('Grammy nominations'!$A$2:$A$189,B42,'Grammy nominations'!$F$2:$F$189,"later",'Grammy nominations'!$E$2:$E$189,"won") -> 1 | W42: =COUNTIFS('Grammy nominations'!$A$2:$A$189,B42,'Grammy nominations'!$F$2:$F$189,"same ceremony") -> 3 | X42: =IF(G42=0,"",M42-L42+1-SUMIFS(Breaks!$H$2:$H$31,Breaks!$A$2:$A$31,B42)) -> 41 | Y42: =IF(G42=0,"",IF(M42<E42,0,M42-MAX(L42,E42)+1-SUMIFS(Breaks!$H$2:$H$31,Breaks!$A$2:$A$31,B42,Breaks!$C$2:$C$31,">="&E42))) -> 40 | Z42: grammy.com shows 1 win, 6 nominations (27th 1985; 67th 2025).
A43: act_039 | B43: Simply Red | C43: Group | D43: 31832 | E43: =YEAR(D43) -> 1987 | F43: nominated | G43: =COUNTIFS(Albums!$B$2:$B$406,B43) -> 12 | H43: =COUNTIFS(Albums!$B$2:$B$406,B43,Albums!$H$2:$H$406,"yes") -> 11 | I43: =COUNTIFS(Albums!$B$2:$B$406,B43,Albums!$I$2:$I$406,"yes") -> 8 | J43: =COUNTIFS(Albums!$B$2:$B$406,B43,Albums!$J$2:$J$406,">0") -> 8 | K43: =COUNTIFS(Albums!$B$2:$B$406,B43,Albums!$H$2:$H$406,"yes",Albums!$J$2:$J$406,">0") -> 7 | L43: =IF(G43=0,"",_xlfn.MINIFS(Albums!$E$2:$E$406,Albums!$B$2:$B$406,B43)) -> 1985 | M43: =IF(G43=0,"",_xlfn.MAXIFS(Albums!$E$2:$E$406,Albums!$B$2:$B$406,B43)) -> 2023 | N43: =IF(J43=0,"",_xlfn.MINIFS(Albums!$J$2:$J$406,Albums!$B$2:$B$406,B43,Albums!$J$2:$J$406,">0")) -> 16 | O43: =IF(K43=0,"",_xlfn.MINIFS(Albums!$J$2:$J$406,Albums!$B$2:$B$406,B43,Albums!$H$2:$H$406,"yes",Albums!$J$2:$J$406,">0")) -> 22 | P43: =COUNTIFS(Albums!$B$2:$B$406,B43,Albums!$H$2:$H$406,"yes",Albums!$J$2:$J$406,">0",Albums!$J$2:$J$406,"<=40") -> 2 | Q43: =COUNTIFS(Albums!$B$2:$B$406,B43,Albums!$M$2:$M$406,">0") -> 3 | R43: =COUNTIFS(Albums!$B$2:$B$406,B43,Albums!$H$2:$H$406,"yes",Albums!$M$2:$M$406,">0") -> 2 | S43: =SUMIFS(Albums!$M$2:$M$406,Albums!$B$2:$B$406,B43) -> 2 | T43: =SUMIFS(Albums!$M$2:$M$406,Albums!$B$2:$B$406,B43,Albums!$H$2:$H$406,"yes") -> 1 | U43: =COUNTIFS('Grammy nominations'!$A$2:$A$189,B43,'Grammy nominations'!$F$2:$F$189,"later") -> 1 | V43: =COUNTIFS('Grammy nominations'!$A$2:$A$189,B43,'Grammy nominations'!$F$2:$F$189,"later",'Grammy nominations'!$E$2:$E$189,"won") -> 0 | W43: =COUNTIFS('Grammy nominations'!$A$2:$A$189,B43,'Grammy nominations'!$F$2:$F$189,"same ceremony") -> 1 | X43: =IF(G43=0,"",M43-L43+1-SUMIFS(Breaks!$H$2:$H$31,Breaks!$A$2:$A$31,B43)) -> 32 | Y43: =IF(G43=0,"",IF(M43<E43,0,M43-MAX(L43,E43)+1-SUMIFS(Breaks!$H$2:$H$31,Breaks!$A$2:$A$31,B43,Breaks!$C$2:$C$31,">="&E43))) -> 30 | Z43: No standalone Simply Red page found on grammy.com; nominations taken from the grammy.com page of member Tony Bowers, where all three entries are credited to "Simply Red" (29th 1987: BNA + Holding Back The Years; 32nd 1990: If You Don't Know Me By Now). https://en.wikipedia.org/wiki/Simply_Red confirms three group nominations and no wins (the 1990 Best R&B Song win for that song went to songwriters Gamble and Huff, not the band). Mick Hucknall solo not counted.
A44: act_053 | B44: Soul II Soul | C44: Group | D44: 32925 | E44: =YEAR(D44) -> 1990 | F44: nominated | G44: =COUNTIFS(Albums!$B$2:$B$406,B44) -> 5 | H44: =COUNTIFS(Albums!$B$2:$B$406,B44,Albums!$H$2:$H$406,"yes") -> 4 | I44: =COUNTIFS(Albums!$B$2:$B$406,B44,Albums!$I$2:$I$406,"yes") -> 4 | J44: =COUNTIFS(Albums!$B$2:$B$406,B44,Albums!$J$2:$J$406,">0") -> 3 | K44: =COUNTIFS(Albums!$B$2:$B$406,B44,Albums!$H$2:$H$406,"yes",Albums!$J$2:$J$406,">0") -> 2 | L44: =IF(G44=0,"",_xlfn.MINIFS(Albums!$E$2:$E$406,Albums!$B$2:$B$406,B44)) -> 1989 | M44: =IF(G44=0,"",_xlfn.MAXIFS(Albums!$E$2:$E$406,Albums!$B$2:$B$406,B44)) -> 1997 | N44: =IF(J44=0,"",_xlfn.MINIFS(Albums!$J$2:$J$406,Albums!$B$2:$B$406,B44,Albums!$J$2:$J$406,">0")) -> 14 | O44: =IF(K44=0,"",_xlfn.MINIFS(Albums!$J$2:$J$406,Albums!$B$2:$B$406,B44,Albums!$H$2:$H$406,"yes",Albums!$J$2:$J$406,">0")) -> 21 | P44: =COUNTIFS(Albums!$B$2:$B$406,B44,Albums!$H$2:$H$406,"yes",Albums!$J$2:$J$406,">0",Albums!$J$2:$J$406,"<=40") -> 1 | Q44: =COUNTIFS(Albums!$B$2:$B$406,B44,Albums!$M$2:$M$406,">0") -> 2 | R44: =COUNTIFS(Albums!$B$2:$B$406,B44,Albums!$H$2:$H$406,"yes",Albums!$M$2:$M$406,">0") -> 1 | S44: =SUMIFS(Albums!$M$2:$M$406,Albums!$B$2:$B$406,B44) -> 2.5 | T44: =SUMIFS(Albums!$M$2:$M$406,Albums!$B$2:$B$406,B44,Albums!$H$2:$H$406,"yes") -> 0.5 | U44: =COUNTIFS('Grammy nominations'!$A$2:$A$189,B44,'Grammy nominations'!$F$2:$F$189,"later") -> 1 | V44: =COUNTIFS('Grammy nominations'!$A$2:$A$189,B44,'Grammy nominations'!$F$2:$F$189,"later",'Grammy nominations'!$E$2:$E$189,"won") -> 0 | W44: =COUNTIFS('Grammy nominations'!$A$2:$A$189,B44,'Grammy nominations'!$F$2:$F$189,"same ceremony") -> 2 | X44: =IF(G44=0,"",M44-L44+1-SUMIFS(Breaks!$H$2:$H$31,Breaks!$A$2:$A$31,B44)) -> 9 | Y44: =IF(G44=0,"",IF(M44<E44,0,M44-MAX(L44,E44)+1-SUMIFS(Breaks!$H$2:$H$31,Breaks!$A$2:$A$31,B44,Breaks!$C$2:$C$31,">="&E44))) -> 8 | Z44: grammy.com artist page (https://www.grammy.com/artists/soul-ii-soul/) failed to load twice; used the awards table on the Wikipedia band page. The 1993 (35th) Mood nomination in Best R&B Instrumental Performance is confirmed on https://www.grammy.com/awards/categories/best-rb-instrumental-performance/1993/ . Wikipedia says the group has won two Grammys in total.
A45: act_020 | B45: Stray Cats | C45: Group | D45: 30370 | E45: =YEAR(D45) -> 1983 | F45: nominated | G45: =COUNTIFS(Albums!$B$2:$B$406,B45) -> 9 | H45: =COUNTIFS(Albums!$B$2:$B$406,B45,Albums!$H$2:$H$406,"yes") -> 7 | I45: =COUNTIFS(Albums!$B$2:$B$406,B45,Albums!$I$2:$I$406,"yes") -> 5 | J45: =COUNTIFS(Albums!$B$2:$B$406,B45,Albums!$J$2:$J$406,">0") -> 4 | K45: =COUNTIFS(Albums!$B$2:$B$406,B45,Albums!$H$2:$H$406,"yes",Albums!$J$2:$J$406,">0") -> 4 | L45: =IF(G45=0,"",_xlfn.MINIFS(Albums!$E$2:$E$406,Albums!$B$2:$B$406,B45)) -> 1981 | M45: =IF(G45=0,"",_xlfn.MAXIFS(Albums!$E$2:$E$406,Albums!$B$2:$B$406,B45)) -> 2019 | N45: =IF(J45=0,"",_xlfn.MINIFS(Albums!$J$2:$J$406,Albums!$B$2:$B$406,B45,Albums!$J$2:$J$406,">0")) -> 14 | O45: =IF(K45=0,"",_xlfn.MINIFS(Albums!$J$2:$J$406,Albums!$B$2:$B$406,B45,Albums!$H$2:$H$406,"yes",Albums!$J$2:$J$406,">0")) -> 14 | P45: =COUNTIFS(Albums!$B$2:$B$406,B45,Albums!$H$2:$H$406,"yes",Albums!$J$2:$J$406,">0",Albums!$J$2:$J$406,"<=40") -> 1 | Q45: =COUNTIFS(Albums!$B$2:$B$406,B45,Albums!$M$2:$M$406,">0") -> 1 | R45: =COUNTIFS(Albums!$B$2:$B$406,B45,Albums!$H$2:$H$406,"yes",Albums!$M$2:$M$406,">0") -> 1 | S45: =SUMIFS(Albums!$M$2:$M$406,Albums!$B$2:$B$406,B45) -> 0.5 | T45: =SUMIFS(Albums!$M$2:$M$406,Albums!$B$2:$B$406,B45,Albums!$H$2:$H$406,"yes") -> 0.5 | U45: =COUNTIFS('Grammy nominations'!$A$2:$A$189,B45,'Grammy nominations'!$F$2:$F$189,"later") -> 0 | V45: =COUNTIFS('Grammy nominations'!$A$2:$A$189,B45,'Grammy nominations'!$F$2:$F$189,"later",'Grammy nominations'!$E$2:$E$189,"won") -> 0 | W45: =COUNTIFS('Grammy nominations'!$A$2:$A$189,B45,'Grammy nominations'!$F$2:$F$189,"same ceremony") -> 0 | X45: =IF(G45=0,"",M45-L45+1-SUMIFS(Breaks!$H$2:$H$31,Breaks!$A$2:$A$31,B45)) -> 15 | Y45: =IF(G45=0,"",IF(M45<E45,0,M45-MAX(L45,E45)+1-SUMIFS(Breaks!$H$2:$H$31,Breaks!$A$2:$A$31,B45,Breaks!$C$2:$C$31,">="&E45))) -> 13 | Z45: grammy.com lists a single entry: Best New Artist, 1983 (25th), nominated. 0 wins, 1 nomination.
A46: act_045 | B46: Swing Out Sister | C46: Group | D46: 32204 | E46: =YEAR(D46) -> 1988 | F46: nominated | G46: =COUNTIFS(Albums!$B$2:$B$406,B46) -> 10 | H46: =COUNTIFS(Albums!$B$2:$B$406,B46,Albums!$H$2:$H$406,"yes") -> 9 | I46: =COUNTIFS(Albums!$B$2:$B$406,B46,Albums!$I$2:$I$406,"yes") -> 7 | J46: =COUNTIFS(Albums!$B$2:$B$406,B46,Albums!$J$2:$J$406,">0") -> 3 | K46: =COUNTIFS(Albums!$B$2:$B$406,B46,Albums!$H$2:$H$406,"yes",Albums!$J$2:$J$406,">0") -> 2 | L46: =IF(G46=0,"",_xlfn.MINIFS(Albums!$E$2:$E$406,Albums!$B$2:$B$406,B46)) -> 1987 | M46: =IF(G46=0,"",_xlfn.MAXIFS(Albums!$E$2:$E$406,Albums!$B$2:$B$406,B46)) -> 2017 | N46: =IF(J46=0,"",_xlfn.MINIFS(Albums!$J$2:$J$406,Albums!$B$2:$B$406,B46,Albums!$J$2:$J$406,">0")) -> 40 | O46: =IF(K46=0,"",_xlfn.MINIFS(Albums!$J$2:$J$406,Albums!$B$2:$B$406,B46,Albums!$H$2:$H$406,"yes",Albums!$J$2:$J$406,">0")) -> 61 | P46: =COUNTIFS(Albums!$B$2:$B$406,B46,Albums!$H$2:$H$406,"yes",Albums!$J$2:$J$406,">0",Albums!$J$2:$J$406,"<=40") -> 0 | Q46: =COUNTIFS(Albums!$B$2:$B$406,B46,Albums!$M$2:$M$406,">0") -> 0 | R46: =COUNTIFS(Albums!$B$2:$B$406,B46,Albums!$H$2:$H$406,"yes",Albums!$M$2:$M$406,">0") -> 0 | S46: =SUMIFS(Albums!$M$2:$M$406,Albums!$B$2:$B$406,B46) -> 0 | T46: =SUMIFS(Albums!$M$2:$M$406,Albums!$B$2:$B$406,B46,Albums!$H$2:$H$406,"yes") -> 0 | U46: =COUNTIFS('Grammy nominations'!$A$2:$A$189,B46,'Grammy nominations'!$F$2:$F$189,"later") -> 0 | V46: =COUNTIFS('Grammy nominations'!$A$2:$A$189,B46,'Grammy nominations'!$F$2:$F$189,"later",'Grammy nominations'!$E$2:$E$189,"won") -> 0 | W46: =COUNTIFS('Grammy nominations'!$A$2:$A$189,B46,'Grammy nominations'!$F$2:$F$189,"same ceremony") -> 1 | X46: =IF(G46=0,"",M46-L46+1-SUMIFS(Breaks!$H$2:$H$31,Breaks!$A$2:$A$31,B46)) -> 31 | Y46: =IF(G46=0,"",IF(M46<E46,0,M46-MAX(L46,E46)+1-SUMIFS(Breaks!$H$2:$H$31,Breaks!$A$2:$A$31,B46,Breaks!$C$2:$C$31,">="&E46))) -> 30
A47: act_049 | B47: Take 6 | C47: Group | D47: 32561 | E47: =YEAR(D47) -> 1989 | F47: nominated | G47: =COUNTIFS(Albums!$B$2:$B$406,B47) -> 14 | H47: =COUNTIFS(Albums!$B$2:$B$406,B47,Albums!$H$2:$H$406,"yes") -> 13 | I47: =COUNTIFS(Albums!$B$2:$B$406,B47,Albums!$I$2:$I$406,"yes") -> 13 | J47: =COUNTIFS(Albums!$B$2:$B$406,B47,Albums!$J$2:$J$406,">0") -> 4 | K47: =COUNTIFS(Albums!$B$2:$B$406,B47,Albums!$H$2:$H$406,"yes",Albums!$J$2:$J$406,">0") -> 3 | L47: =IF(G47=0,"",_xlfn.MINIFS(Albums!$E$2:$E$406,Albums!$B$2:$B$406,B47)) -> 1988 | M47: =IF(G47=0,"",_xlfn.MAXIFS(Albums!$E$2:$E$406,Albums!$B$2:$B$406,B47)) -> 2018 | N47: =IF(J47=0,"",_xlfn.MINIFS(Albums!$J$2:$J$406,Albums!$B$2:$B$406,B47,Albums!$J$2:$J$406,">0")) -> 71 | O47: =IF(K47=0,"",_xlfn.MINIFS(Albums!$J$2:$J$406,Albums!$B$2:$B$406,B47,Albums!$H$2:$H$406,"yes",Albums!$J$2:$J$406,">0")) -> 72 | P47: =COUNTIFS(Albums!$B$2:$B$406,B47,Albums!$H$2:$H$406,"yes",Albums!$J$2:$J$406,">0",Albums!$J$2:$J$406,"<=40") -> 0 | Q47: =COUNTIFS(Albums!$B$2:$B$406,B47,Albums!$M$2:$M$406,">0") -> 2 | R47: =COUNTIFS(Albums!$B$2:$B$406,B47,Albums!$H$2:$H$406,"yes",Albums!$M$2:$M$406,">0") -> 1 | S47: =SUMIFS(Albums!$M$2:$M$406,Albums!$B$2:$B$406,B47) -> 1.5 | T47: =SUMIFS(Albums!$M$2:$M$406,Albums!$B$2:$B$406,B47,Albums!$H$2:$H$406,"yes") -> 0.5 | U47: =COUNTIFS('Grammy nominations'!$A$2:$A$189,B47,'Grammy nominations'!$F$2:$F$189,"later") -> 16 | V47: =COUNTIFS('Grammy nominations'!$A$2:$A$189,B47,'Grammy nominations'!$F$2:$F$189,"later",'Grammy nominations'!$E$2:$E$189,"won") -> 6 | W47: =COUNTIFS('Grammy nominations'!$A$2:$A$189,B47,'Grammy nominations'!$F$2:$F$189,"same ceremony") -> 2 | X47: =IF(G47=0,"",M47-L47+1-SUMIFS(Breaks!$H$2:$H$31,Breaks!$A$2:$A$31,B47)) -> 31 | Y47: =IF(G47=0,"",IF(M47<E47,0,M47-MAX(L47,E47)+1-SUMIFS(Breaks!$H$2:$H$31,Breaks!$A$2:$A$31,B47,Breaks!$C$2:$C$31,">="&E47))) -> 30 | Z47: grammy.com lists 19 nominations / 8 wins; several entries had no status label on grammy.com, so won/nominated taken from Wikipedia Take 6 page (8 wins, consistent with grammy.com total).
A48: act_044 | B48: Terence Trent D'Arby | C48: Solo | D48: 32204 | E48: =YEAR(D48) -> 1988 | F48: nominated | G48: =COUNTIFS(Albums!$B$2:$B$406,B48) -> 14 | H48: =COUNTIFS(Albums!$B$2:$B$406,B48,Albums!$H$2:$H$406,"yes") -> 13 | I48: =COUNTIFS(Albums!$B$2:$B$406,B48,Albums!$I$2:$I$406,"yes") -> 4 | J48: =COUNTIFS(Albums!$B$2:$B$406,B48,Albums!$J$2:$J$406,">0") -> 4 | K48: =COUNTIFS(Albums!$B$2:$B$406,B48,Albums!$H$2:$H$406,"yes",Albums!$J$2:$J$406,">0") -> 3 | L48: =IF(G48=0,"",_xlfn.MINIFS(Albums!$E$2:$E$406,Albums!$B$2:$B$406,B48)) -> 1987 | M48: =IF(G48=0,"",_xlfn.MAXIFS(Albums!$E$2:$E$406,Albums!$B$2:$B$406,B48)) -> 2024 | N48: =IF(J48=0,"",_xlfn.MINIFS(Albums!$J$2:$J$406,Albums!$B$2:$B$406,B48,Albums!$J$2:$J$406,">0")) -> 4 | O48: =IF(K48=0,"",_xlfn.MINIFS(Albums!$J$2:$J$406,Albums!$B$2:$B$406,B48,Albums!$H$2:$H$406,"yes",Albums!$J$2:$J$406,">0")) -> 61 | P48: =COUNTIFS(Albums!$B$2:$B$406,B48,Albums!$H$2:$H$406,"yes",Albums!$J$2:$J$406,">0",Albums!$J$2:$J$406,"<=40") -> 0 | Q48: =COUNTIFS(Albums!$B$2:$B$406,B48,Albums!$M$2:$M$406,">0") -> 1 | R48: =COUNTIFS(Albums!$B$2:$B$406,B48,Albums!$H$2:$H$406,"yes",Albums!$M$2:$M$406,">0") -> 0 | S48: =SUMIFS(Albums!$M$2:$M$406,Albums!$B$2:$B$406,B48) -> 2 | T48: =SUMIFS(Albums!$M$2:$M$406,Albums!$B$2:$B$406,B48,Albums!$H$2:$H$406,"yes") -> 0 | U48: =COUNTIFS('Grammy nominations'!$A$2:$A$189,B48,'Grammy nominations'!$F$2:$F$189,"later") -> 2 | V48: =COUNTIFS('Grammy nominations'!$A$2:$A$189,B48,'Grammy nominations'!$F$2:$F$189,"later",'Grammy nominations'!$E$2:$E$189,"won") -> 1 | W48: =COUNTIFS('Grammy nominations'!$A$2:$A$189,B48,'Grammy nominations'!$F$2:$F$189,"same ceremony") -> 0 | X48: =IF(G48=0,"",M48-L48+1-SUMIFS(Breaks!$H$2:$H$31,Breaks!$A$2:$A$31,B48)) -> 38 | Y48: =IF(G48=0,"",IF(M48<E48,0,M48-MAX(L48,E48)+1-SUMIFS(Breaks!$H$2:$H$31,Breaks!$A$2:$A$31,B48,Breaks!$C$2:$C$31,">="&E48))) -> 37 | Z48: grammy.com shows 3 nominations / 1 win: 1988 Best New Artist (nominee), 1989 R&B male vocal (winner), 1996 R&B duo/group (nominee). Wikipedia Best Male R&B Vocal Performance page confirms 1989 ceremony for the win.
A49: act_040 | B49: Timbuk3 | C49: Group | D49: 31832 | E49: =YEAR(D49) -> 1987 | F49: nominated | G49: =COUNTIFS(Albums!$B$2:$B$406,B49) -> 5 | H49: =COUNTIFS(Albums!$B$2:$B$406,B49,Albums!$H$2:$H$406,"yes") -> 4 | I49: =COUNTIFS(Albums!$B$2:$B$406,B49,Albums!$I$2:$I$406,"yes") -> 2 | J49: =COUNTIFS(Albums!$B$2:$B$406,B49,Albums!$J$2:$J$406,">0") -> 2 | K49: =COUNTIFS(Albums!$B$2:$B$406,B49,Albums!$H$2:$H$406,"yes",Albums!$J$2:$J$406,">0") -> 1 | L49: =IF(G49=0,"",_xlfn.MINIFS(Albums!$E$2:$E$406,Albums!$B$2:$B$406,B49)) -> 1986 | M49: =IF(G49=0,"",_xlfn.MAXIFS(Albums!$E$2:$E$406,Albums!$B$2:$B$406,B49)) -> 1995 | N49: =IF(J49=0,"",_xlfn.MINIFS(Albums!$J$2:$J$406,Albums!$B$2:$B$406,B49,Albums!$J$2:$J$406,">0")) -> 50 | O49: =IF(K49=0,"",_xlfn.MINIFS(Albums!$J$2:$J$406,Albums!$B$2:$B$406,B49,Albums!$H$2:$H$406,"yes",Albums!$J$2:$J$406,">0")) -> 107 | P49: =COUNTIFS(Albums!$B$2:$B$406,B49,Albums!$H$2:$H$406,"yes",Albums!$J$2:$J$406,">0",Albums!$J$2:$J$406,"<=40") -> 0 | Q49: =COUNTIFS(Albums!$B$2:$B$406,B49,Albums!$M$2:$M$406,">0") -> 0 | R49: =COUNTIFS(Albums!$B$2:$B$406,B49,Albums!$H$2:$H$406,"yes",Albums!$M$2:$M$406,">0") -> 0 | S49: =SUMIFS(Albums!$M$2:$M$406,Albums!$B$2:$B$406,B49) -> 0 | T49: =SUMIFS(Albums!$M$2:$M$406,Albums!$B$2:$B$406,B49,Albums!$H$2:$H$406,"yes") -> 0 | U49: =COUNTIFS('Grammy nominations'!$A$2:$A$189,B49,'Grammy nominations'!$F$2:$F$189,"later") -> 0 | V49: =COUNTIFS('Grammy nominations'!$A$2:$A$189,B49,'Grammy nominations'!$F$2:$F$189,"later",'Grammy nominations'!$E$2:$E$189,"won") -> 0 | W49: =COUNTIFS('Grammy nominations'!$A$2:$A$189,B49,'Grammy nominations'!$F$2:$F$189,"same ceremony") -> 0 | X49: =IF(G49=0,"",M49-L49+1-SUMIFS(Breaks!$H$2:$H$31,Breaks!$A$2:$A$31,B49)) -> 10 | Y49: =IF(G49=0,"",IF(M49<E49,0,M49-MAX(L49,E49)+1-SUMIFS(Breaks!$H$2:$H$31,Breaks!$A$2:$A$31,B49,Breaks!$C$2:$C$31,">="&E49))) -> 9 | Z49: grammy.com lists only the Best New Artist nomination (1987).
A50: act_054 | B50: Tone Loc | C50: Solo | D50: 32925 | E50: =YEAR(D50) -> 1990 | F50: nominated | G50: =COUNTIFS(Albums!$B$2:$B$406,B50) -> 2 | H50: =COUNTIFS(Albums!$B$2:$B$406,B50,Albums!$H$2:$H$406,"yes") -> 1 | I50: =COUNTIFS(Albums!$B$2:$B$406,B50,Albums!$I$2:$I$406,"yes") -> 2 | J50: =COUNTIFS(Albums!$B$2:$B$406,B50,Albums!$J$2:$J$406,">0") -> 1 | K50: =COUNTIFS(Albums!$B$2:$B$406,B50,Albums!$H$2:$H$406,"yes",Albums!$J$2:$J$406,">0") -> 0 | L50: =IF(G50=0,"",_xlfn.MINIFS(Albums!$E$2:$E$406,Albums!$B$2:$B$406,B50)) -> 1989 | M50: =IF(G50=0,"",_xlfn.MAXIFS(Albums!$E$2:$E$406,Albums!$B$2:$B$406,B50)) -> 1991 | N50: =IF(J50=0,"",_xlfn.MINIFS(Albums!$J$2:$J$406,Albums!$B$2:$B$406,B50,Albums!$J$2:$J$406,">0")) -> 1 | O50: =IF(K50=0,"",_xlfn.MINIFS(Albums!$J$2:$J$406,Albums!$B$2:$B$406,B50,Albums!$H$2:$H$406,"yes",Albums!$J$2:$J$406,">0")) | P50: =COUNTIFS(Albums!$B$2:$B$406,B50,Albums!$H$2:$H$406,"yes",Albums!$J$2:$J$406,">0",Albums!$J$2:$J$406,"<=40") -> 0 | Q50: =COUNTIFS(Albums!$B$2:$B$406,B50,Albums!$M$2:$M$406,">0") -> 1 | R50: =COUNTIFS(Albums!$B$2:$B$406,B50,Albums!$H$2:$H$406,"yes",Albums!$M$2:$M$406,">0") -> 0 | S50: =SUMIFS(Albums!$M$2:$M$406,Albums!$B$2:$B$406,B50) -> 2 | T50: =SUMIFS(Albums!$M$2:$M$406,Albums!$B$2:$B$406,B50,Albums!$H$2:$H$406,"yes") -> 0 | U50: =COUNTIFS('Grammy nominations'!$A$2:$A$189,B50,'Grammy nominations'!$F$2:$F$189,"later") -> 0 | V50: =COUNTIFS('Grammy nominations'!$A$2:$A$189,B50,'Grammy nominations'!$F$2:$F$189,"later",'Grammy nominations'!$E$2:$E$189,"won") -> 0 | W50: =COUNTIFS('Grammy nominations'!$A$2:$A$189,B50,'Grammy nominations'!$F$2:$F$189,"same ceremony") -> 1 | X50: =IF(G50=0,"",M50-L50+1-SUMIFS(Breaks!$H$2:$H$31,Breaks!$A$2:$A$31,B50)) -> 3 | Y50: =IF(G50=0,"",IF(M50<E50,0,M50-MAX(L50,E50)+1-SUMIFS(Breaks!$H$2:$H$31,Breaks!$A$2:$A$31,B50,Breaks!$C$2:$C$31,">="&E50))) -> 2 | Z50: grammy.com lists 2 nominations, 0 wins (Best New Artist and Best Rap Performance, both 1990). Wikipedia also mentions a 1991 Best Rap Performance by a Duo or Group nomination for 'We're All in the Same Gang', but that was credited to the West Coast Rap All-Stars collective and is not on Tone Loc's grammy.com page, so it is excluded.
A51: act_048 | B51: Toni Childs | C51: Solo | D51: 32561 | E51: =YEAR(D51) -> 1989 | F51: nominated | G51: =COUNTIFS(Albums!$B$2:$B$406,B51) -> 5 | H51: =COUNTIFS(Albums!$B$2:$B$406,B51,Albums!$H$2:$H$406,"yes") -> 4 | I51: =COUNTIFS(Albums!$B$2:$B$406,B51,Albums!$I$2:$I$406,"yes") -> 3 | J51: =COUNTIFS(Albums!$B$2:$B$406,B51,Albums!$J$2:$J$406,">0") -> 2 | K51: =COUNTIFS(Albums!$B$2:$B$406,B51,Albums!$H$2:$H$406,"yes",Albums!$J$2:$J$406,">0") -> 1 | L51: =IF(G51=0,"",_xlfn.MINIFS(Albums!$E$2:$E$406,Albums!$B$2:$B$406,B51)) -> 1988 | M51: =IF(G51=0,"",_xlfn.MAXIFS(Albums!$E$2:$E$406,Albums!$B$2:$B$406,B51)) -> 2014 | N51: =IF(J51=0,"",_xlfn.MINIFS(Albums!$J$2:$J$406,Albums!$B$2:$B$406,B51,Albums!$J$2:$J$406,">0")) -> 63 | O51: =IF(K51=0,"",_xlfn.MINIFS(Albums!$J$2:$J$406,Albums!$B$2:$B$406,B51,Albums!$H$2:$H$406,"yes",Albums!$J$2:$J$406,">0")) -> 115 | P51: =COUNTIFS(Albums!$B$2:$B$406,B51,Albums!$H$2:$H$406,"yes",Albums!$J$2:$J$406,">0",Albums!$J$2:$J$406,"<=40") -> 0 | Q51: =COUNTIFS(Albums!$B$2:$B$406,B51,Albums!$M$2:$M$406,">0") -> 1 | R51: =COUNTIFS(Albums!$B$2:$B$406,B51,Albums!$H$2:$H$406,"yes",Albums!$M$2:$M$406,">0") -> 0 | S51: =SUMIFS(Albums!$M$2:$M$406,Albums!$B$2:$B$406,B51) -> 0.5 | T51: =SUMIFS(Albums!$M$2:$M$406,Albums!$B$2:$B$406,B51,Albums!$H$2:$H$406,"yes") -> 0 | U51: =COUNTIFS('Grammy nominations'!$A$2:$A$189,B51,'Grammy nominations'!$F$2:$F$189,"later") -> 1 | V51: =COUNTIFS('Grammy nominations'!$A$2:$A$189,B51,'Grammy nominations'!$F$2:$F$189,"later",'Grammy nominations'!$E$2:$E$189,"won") -> 0 | W51: =COUNTIFS('Grammy nominations'!$A$2:$A$189,B51,'Grammy nominations'!$F$2:$F$189,"same ceremony") -> 1 | X51: =IF(G51=0,"",M51-L51+1-SUMIFS(Breaks!$H$2:$H$31,Breaks!$A$2:$A$31,B51)) -> 27 | Y51: =IF(G51=0,"",IF(M51<E51,0,M51-MAX(L51,E51)+1-SUMIFS(Breaks!$H$2:$H$31,Breaks!$A$2:$A$31,B51,Breaks!$C$2:$C$31,">="&E51))) -> 26 | Z51: grammy.com shows 0 wins, 3 nominations (31st 1989; 38th 1996).
A52: act_046 | B52: Tracy Chapman | C52: Solo | D52: 32561 | E52: =YEAR(D52) -> 1989 | F52: won | G52: =COUNTIFS(Albums!$B$2:$B$406,B52) -> 8 | H52: =COUNTIFS(Albums!$B$2:$B$406,B52,Albums!$H$2:$H$406,"yes") -> 7 | I52: =COUNTIFS(Albums!$B$2:$B$406,B52,Albums!$I$2:$I$406,"yes") -> 8 | J52: =COUNTIFS(Albums!$B$2:$B$406,B52,Albums!$J$2:$J$406,">0") -> 8 | K52: =COUNTIFS(Albums!$B$2:$B$406,B52,Albums!$H$2:$H$406,"yes",Albums!$J$2:$J$406,">0") -> 7 | L52: =IF(G52=0,"",_xlfn.MINIFS(Albums!$E$2:$E$406,Albums!$B$2:$B$406,B52)) -> 1988 | M52: =IF(G52=0,"",_xlfn.MAXIFS(Albums!$E$2:$E$406,Albums!$B$2:$B$406,B52)) -> 2008 | N52: =IF(J52=0,"",_xlfn.MINIFS(Albums!$J$2:$J$406,Albums!$B$2:$B$406,B52,Albums!$J$2:$J$406,">0")) -> 1 | O52: =IF(K52=0,"",_xlfn.MINIFS(Albums!$J$2:$J$406,Albums!$B$2:$B$406,B52,Albums!$H$2:$H$406,"yes",Albums!$J$2:$J$406,">0")) -> 4 | P52: =COUNTIFS(Albums!$B$2:$B$406,B52,Albums!$H$2:$H$406,"yes",Albums!$J$2:$J$406,">0",Albums!$J$2:$J$406,"<=40") -> 4 | Q52: =COUNTIFS(Albums!$B$2:$B$406,B52,Albums!$M$2:$M$406,">0") -> 5 | R52: =COUNTIFS(Albums!$B$2:$B$406,B52,Albums!$H$2:$H$406,"yes",Albums!$M$2:$M$406,">0") -> 4 | S52: =SUMIFS(Albums!$M$2:$M$406,Albums!$B$2:$B$406,B52) -> 13 | T52: =SUMIFS(Albums!$M$2:$M$406,Albums!$B$2:$B$406,B52,Albums!$H$2:$H$406,"yes") -> 7 | U52: =COUNTIFS('Grammy nominations'!$A$2:$A$189,B52,'Grammy nominations'!$F$2:$F$189,"later") -> 7 | V52: =COUNTIFS('Grammy nominations'!$A$2:$A$189,B52,'Grammy nominations'!$F$2:$F$189,"later",'Grammy nominations'!$E$2:$E$189,"won") -> 1 | W52: =COUNTIFS('Grammy nominations'!$A$2:$A$189,B52,'Grammy nominations'!$F$2:$F$189,"same ceremony") -> 5 | X52: =IF(G52=0,"",M52-L52+1-SUMIFS(Breaks!$H$2:$H$31,Breaks!$A$2:$A$31,B52)) -> 21 | Y52: =IF(G52=0,"",IF(M52<E52,0,M52-MAX(L52,E52)+1-SUMIFS(Breaks!$H$2:$H$31,Breaks!$A$2:$A$31,B52,Breaks!$C$2:$C$31,">="&E52))) -> 20 | Z52: grammy.com shows 4 wins / 13 nominations but no result label for 1989 Album Of The Year and Best Contemporary Folk Recording. AOTY set to nominated because Wikipedia 31st Annual Grammy Awards page says AOTY went to George Michael for Faith. Folk Recording set to won: consistent with grammy.com total of 4 wins and confirmed by Wikipedia album page Tracy_Chapman_(album) Grammy table (folk category Won, Album of the Year Nominated). A 1989 Producer of the Year nomination on that page is credited to David Kershenbaum, not Chapman, so excluded
A53: act_050 | B53: Vanessa Williams | C53: Solo | D53: 32561 | E53: =YEAR(D53) -> 1989 | F53: nominated | G53: =COUNTIFS(Albums!$B$2:$B$406,B53) -> 9 | H53: =COUNTIFS(Albums!$B$2:$B$406,B53,Albums!$H$2:$H$406,"yes") -> 8 | I53: =COUNTIFS(Albums!$B$2:$B$406,B53,Albums!$I$2:$I$406,"yes") -> 8 | J53: =COUNTIFS(Albums!$B$2:$B$406,B53,Albums!$J$2:$J$406,">0") -> 8 | K53: =COUNTIFS(Albums!$B$2:$B$406,B53,Albums!$H$2:$H$406,"yes",Albums!$J$2:$J$406,">0") -> 7 | L53: =IF(G53=0,"",_xlfn.MINIFS(Albums!$E$2:$E$406,Albums!$B$2:$B$406,B53)) -> 1988 | M53: =IF(G53=0,"",_xlfn.MAXIFS(Albums!$E$2:$E$406,Albums!$B$2:$B$406,B53)) -> 2024 | N53: =IF(J53=0,"",_xlfn.MINIFS(Albums!$J$2:$J$406,Albums!$B$2:$B$406,B53,Albums!$J$2:$J$406,">0")) -> 17 | O53: =IF(K53=0,"",_xlfn.MINIFS(Albums!$J$2:$J$406,Albums!$B$2:$B$406,B53,Albums!$H$2:$H$406,"yes",Albums!$J$2:$J$406,">0")) -> 17 | P53: =COUNTIFS(Albums!$B$2:$B$406,B53,Albums!$H$2:$H$406,"yes",Albums!$J$2:$J$406,">0",Albums!$J$2:$J$406,"<=40") -> 2 | Q53: =COUNTIFS(Albums!$B$2:$B$406,B53,Albums!$M$2:$M$406,">0") -> 4 | R53: =COUNTIFS(Albums!$B$2:$B$406,B53,Albums!$H$2:$H$406,"yes",Albums!$M$2:$M$406,">0") -> 3 | S53: =SUMIFS(Albums!$M$2:$M$406,Albums!$B$2:$B$406,B53) -> 5 | T53: =SUMIFS(Albums!$M$2:$M$406,Albums!$B$2:$B$406,B53,Albums!$H$2:$H$406,"yes") -> 4.5 | U53: =COUNTIFS('Grammy nominations'!$A$2:$A$189,B53,'Grammy nominations'!$F$2:$F$189,"later") -> 9 | V53: =COUNTIFS('Grammy nominations'!$A$2:$A$189,B53,'Grammy nominations'!$F$2:$F$189,"later",'Grammy nominations'!$E$2:$E$189,"won") -> 0 | W53: =COUNTIFS('Grammy nominations'!$A$2:$A$189,B53,'Grammy nominations'!$F$2:$F$189,"same ceremony") -> 1 | X53: =IF(G53=0,"",M53-L53+1-SUMIFS(Breaks!$H$2:$H$31,Breaks!$A$2:$A$31,B53)) -> 37 | Y53: =IF(G53=0,"",IF(M53<E53,0,M53-MAX(L53,E53)+1-SUMIFS(Breaks!$H$2:$H$31,Breaks!$A$2:$A$31,B53,Breaks!$C$2:$C$31,">="&E53))) -> 36 | Z53: grammy.com lists 11 nominations, 0 wins

Sheet Albums
A1: event_id | B1: Act | C1: Album | D1: First release | E1: Release year | F1: Date used for ordering | G1: Best New Artist ceremony | H1: Released after the ceremony? | I1: Released in the US? | J1: Billboard 200 peak | K1: Charted on the Billboard 200? | L1: RIAA certification | M1: RIAA units (millions) | N1: Source | O1: Note
A2: E001 | B2: a-ha | C2: Hunting High and Low | D2: 1985-06-01 | E2: =VALUE(LEFT(D2,4)) -> 1985 | F2: =IF(LEN(D2)=10,DATE(VALUE(LEFT(D2,4)),VALUE(MID(D2,6,2)),VALUE(RIGHT(D2,2))),IF(LEN(D2)=7,DATE(VALUE(LEFT(D2,4)),VALUE(MID(D2,6,2)),15),DATE(VALUE(LEFT(D2,4)),7,1))) -> 31199 | G2: =INDEX(Acts!$D:$D,MATCH(B2,Acts!$B:$B,0)) -> 31468 | H2: =IF(F2>G2,"yes","no") -> no | I2: yes | J2: 15 | K2: =IF(J2="","no","yes") -> yes | L2: Platinum | M2: =IF(L2="",0,IF(L2="Gold",0.5,IF(L2="Platinum",1,IF(L2="Diamond",10,IF(ISNUMBER(FIND("×",L2)),VALUE(LEFT(L2,FIND("×",L2)-1)),0))))) -> 1 | N2: https://en.wikipedia.org/wiki/A-ha_discography
A3: E003 | B3: a-ha | C3: Scoundrel Days | D3: 1986-10-06 | E3: =VALUE(LEFT(D3,4)) -> 1986 | F3: =IF(LEN(D3)=10,DATE(VALUE(LEFT(D3,4)),VALUE(MID(D3,6,2)),VALUE(RIGHT(D3,2))),IF(LEN(D3)=7,DATE(VALUE(LEFT(D3,4)),VALUE(MID(D3,6,2)),15),DATE(VALUE(LEFT(D3,4)),7,1))) -> 31691 | G3: =INDEX(Acts!$D:$D,MATCH(B3,Acts!$B:$B,0)) -> 31468 | H3: =IF(F3>G3,"yes","no") -> yes | I3: yes | J3: 74 | K3: =IF(J3="","no","yes") -> yes | M3: =IF(L3="",0,IF(L3="Gold",0.5,IF(L3="Platinum",1,IF(L3="Diamond",10,IF(ISNUMBER(FIND("×",L3)),VALUE(LEFT(L3,FIND("×",L3)-1)),0))))) -> 0 | N3: https://en.wikipedia.org/wiki/A-ha_discography
A4: E004 | B4: a-ha | C4: Stay on These Roads | D4: 1988-05-03 | E4: =VALUE(LEFT(D4,4)) -> 1988 | F4: =IF(LEN(D4)=10,DATE(VALUE(LEFT(D4,4)),VALUE(MID(D4,6,2)),VALUE(RIGHT(D4,2))),IF(LEN(D4)=7,DATE(VALUE(LEFT(D4,4)),VALUE(MID(D4,6,2)),15),DATE(VALUE(LEFT(D4,4)),7,1))) -> 32266 | G4: =INDEX(Acts!$D:$D,MATCH(B4,Acts!$B:$B,0)) -> 31468 | H4: =IF(F4>G4,"yes","no") -> yes | I4: yes | J4: 148 | K4: =IF(J4="","no","yes") -> yes | M4: =IF(L4="",0,IF(L4="Gold",0.5,IF(L4="Platinum",1,IF(L4="Diamond",10,IF(ISNUMBER(FIND("×",L4)),VALUE(LEFT(L4,FIND("×",L4)-1)),0))))) -> 0 | N4: https://en.wikipedia.org/wiki/A-ha_discography
